Workbook
Name g: #REF!
Name jk: #REF!
Name k: #REF!
Name ndc: #REF!
Name PLSS_DB: #REF!

Sheet 0.APQP GRC
E3: APQP Gate Release Checklist (APQP GRC) | T3: GATES RACI CHART RESPONSIBLE ACCOUNTABLE SUPPORTING CONSULTED INFORMED | Y3: Not started | Z3: Open | AA3: OK | AB3: Automotive | AD3: TBD | AF3: TBD
Y4: Launched | Z4: Conditionally closed | AA4: Cond. OK | AB4: Non-Automotive | AD4: PREMO Mediterranée | AF4: Da Nang
Y5: Completed | AA5: N/A | AD5: PREMO Wuhu | AF5: Málaga
C6: Project Manager : | D6: Name Surname | G6: Project Name: | N6: Project Name: | Y6: Approved | AF6: Tangier
C7: PREMO P/N: | D7: X-12345-678 | G7: Part Description: | N7: Part Description: | Y7: Conditional Approved | AF7: Wuhu
C8: Customer P/N: | D8: RT23423AA | G8: Customer Name: | H8: Name of the customer | N8: Customer Name: | Y8: Rejected
C9: Samples Center: | G9: Category: | N9: Category:
C10: Manuf. Center: | G10: Last Rev. Date: | N10: Last Rev. Date:
B12: 1 | C12: FEASIBILITY FOR OPPORTUNITIES - QUALITY GATE LEAD: BUSINESS UNIT DIRECTOR | N12: Action item/Deliverable | O12: Status | P12: Planned Date | Q12: Link to deliverable | R12: Remarks / Gaps | S12: Criteria for acceptance | T12: Responsible | U12: Accountable | V12: Supporting | W12: Consulted | X12: Informed
B13: Feasibility for Opportunities | C13: 1.1 | D13: CIR (Customer Input Requirements) | N13: CIR Form (Technical/Commercial) | S13: 1.- All mandatory fields filled in 2.- Reviewed by BU Director | T13: Key Account Manager | U13: BU Director | V13: Field Application Engineer | W13: Category Design Leader | X13: R&D Director / Corporate Quality Director
C14: 1.2 | D14: Technical Feasibility | N14: Technical Feasibility Analysis | S14: 1.- Technical feasibility analysis result is determined (OK/NG): product/process requirements cross check and estimated margin (quick costing done) 2.- Reviewed by CDL | T14: Field Application Engineer | U14: Key Account Manager | V14: Product design engineer / Corporate controller | W14: Category Design Leader | X14: BU Director
C15: 1.3 | D15: Project Committe Acceptance | N15: 1.- Project Cttee Acceptance Submission 2.- Gate 1 Release Team definition and design/samples/manuf center definition inside PCA submission | S15: 1.- Technical feasibility analysis result must be OK 2.- All mandatory fields filled in 3.- Reviewed by CDL | T15: 1.- Key Account Manager 2.- RD Director, Purchasing Director, Quality Director, Plant Manager, Operations Director | U15: BU Director | V15: Field Application Engineer | W15: CEO | X15: CFO / Sr. Management Team / Project Manager
C16: 1.4 | D16: Previous DFMEA and Lessons Learnt | N16: DFMEA and Lessons Learn up to date of the product family | S16: 1.- Family FMEA is reviewed by FAE | T16: Field Application Engineer | U16: R&D Manager | V16: Category Design Leader | W16: Project Quality Engineer | X16: Corporate Quality Director
C17: 1.5 | D17: Technical definition | N17: 1. Design Concept 2. BOM & Process Flowchart (inside PDCC) 3. Preliminary Datasheet | S17: 1.- Design Concept: all mandatory fields fileld in (BOM and Flowchart) 2.- BOM & Process Flowchart in PDCC matching with Design Concept 3.- Preliminary Datasheet is complete and reviewed by RD Manager/Supervisor/CDL | T17: Product design engineer | U17: Field Application Engineer | V17: Process design engineer | W17: Category Design Leader | X17: R&D Director / Key Account Manager / Purchasing Officer / Project Quality Engineer
C18: 1.6 | D18: PDCC completion | N18: PDCC | S18: 1.- All mandatory fields filled in 2.- Reviewed by Functional Managers (Purchasing, RD) 3.- Reviewed by Corporate controlling for consistency | T18: PDCC team defined inside PDCC | U18: Key Account Manager | V18: Field Application Engineer | W18: Corporate Controller | X18: Corporate Controller / BU Director
C19: 1.7 | D19: Samples WI | N19: Samples WI (A) | S19: 1.- All materials of BOM and process steps inside PDCC/Design Concept are included. Visuals may be provided with 3D drawing snapshots at this stage. 2.- Quality criteria for each step and technology to be used is defined. No need to specify process parameters, only record them in SIR later. 3.- Reviewed by RD Supervisor/Manager | T19: Product design Engineer | U19: R&D Manager | V19: Process design Engineer | W19: Prototype Engineer | X19: Field Application Engineer / Prototype Engineer / Sample Leader / Project Quality Inspector
C20: 1.8 | D20: Sample Production | N20: 1. Sample Production Plan 2. SIR | S20: 1.- Sample Production Plan: all mandatory fields are filled in and reviewed by FAE/RD Manager 2.- SIR: all mandatory fields are filled in (including 3rd and extreme test/disassembly) and reviewed by Product design engineer | T20: 1.- Product design engineer 2.- Prototype Engineer | U20: 1.- Field Application Engineer 2.- Product design engineer | V20: Process design Engineer | W20: R&D Manager | X20: Field Application Engineer
C21: 1.9 | D21: Customer Feedback | N21: Customer feedback: Email, report summary | S21: Evidence is available | T21: Key Account Manager | U21: BU Director | V21: Category Design Leader / Field Application Engineer | W21: Product design engineer | X21: R&D Manager
C22: 1.10 | D22: Feasibility bundle (*) | N22: Close Feasibility Bundle (project plan inside) | S22: 1.- Close Feasibility Bundle result is determined (OK/NG) based on timeline, pricing and technical feasibility by customer. 2.- Close Feasibility Bundle is reviewed by senior management team (RD Director/QA Director/Plant Manager/Purchasing Director) | T22: Project Manager | U22: Key Account Manager | V22: R&D Manager | W22: R&D Director / Plant Manager | X22: BU Director / Plant Manager
C23: 1.11 | D23: Customer Agreement - LON (*) | N23: 1.- RFQ Cttee Submission 2.- LON | S23: 1.- Close Feasibility Bundle result is OK from customer and internal review. 2.- RFQ Cttee Submission conditions match with LON conditions 3.- LON is reviewed by Corporate Controlling 4.- LON is signed by CFO/CEO | T23: Key Account Manager | U23: BU Director | V23: Project Manager | W23: Corporate Controller | X23: Sr. Management Team / Project Manager
C24: PHASE VALIDATION RESULT | G24: PHASE LEAD
C25: Release Status: | E25: Not started | G25: BU Director
C26: Released by:
C27: Release Date:
B28: 2 | C28: DESIGN VALIDATION - QUALITY GATE LEAD: RD DIRECTOR | N28: Action item/Deliverable | O28: Status | P28: Planned Date | Q28: Link to deliverable | R28: Remarks / Gaps | S28: Criteria for acceptance | T28: Responsible | U28: Accountable | V28: Supporting | W28: Consulted | X28: Informed
B29: Design Validation | C29: 2.1 | D29: Team Definition | N29: Gate Release Team defined in GRC Form and in PDCC for all the gates (adding 2, 3 and 4) | S29: 1.- Gate Release Team for all gates defined (adding 2, 3 and 4) 2.- Team definition coordinated with functions and communicated to responsibles and management | T29: Project Manager | U29: Plant Manager | V29: R&D Manager / QA Manager / Engineering Manager / Purchasing Manager / Production Manager/ Maintenance Manager / Supply Chain Manager | W29: Operations Director / R&D Director / QA Director / Purchasing Director | X29: Sr. Management Team / Plant Management Team
C30: 2.2 | D30: Project Master Plan | N30: PMP (Project Master Plan): 1. DV 2. PV 3. QTP 4. Supplier validation 5. Customer milestones vs Premo milestones | S30: 1.- All plans are available 2.- Customer milestones are achievable 3.- Plans are reviewed by Functional managers | T30: 1. Product design Engineer 2. Industrial Engineer 3. Project Quality Engineer 4. Purchasing Officer | U30: Project Manager | V30: 1.- Field Application Engineer 2.- Process design Engineer 3.- Laboratory Engineer 4.- Supplier Quality Engineer | W30: 1. R&D Manager 2. Engineering Manager 3. QA Manager 4. Purchasing Manager 5.- Key Account Manager | X30: R&D Director / BU Director / QA Director / Purchasing Director / Plant Manager / Key Account Manager
C31: 2.3 | D31: Launch the investment | N31: 1.- CAPEX Cttee Submission 2.- Investment system release | S31: 1.- CAPEX Cttee Submission: all mandatory data is filled in (project introduction, technical presentation, investment list, economical analysis) and is presented in Monthly CAPEX meeting to Senior Mgmt 2.- Investment system release: CAPEX Cttee Submission is approved by CEO and CFO and CO order released for the approved amount | T31: 1.- Project Manager 2.- Corporate controller | U31: 1.- RD Director 2.- Project Manager | V31: Quality Director / Purchasing Director / R&D Director | W31: CEO / CFO | X31: Purchasing Manager / Quality Manager / Plant Finance Manager / Plant Manager
C32: 2.4 | D32: Project Kick off | N32: Email or MoM | S32: MoM is available | T32: Project Manager | U32: Plant Manager | V32: R&D Manager / QA Manager / Engineering Manager / Purchasing Manager / Production Manager/ Maintenance Manager / Supply Chain Manager | W32: BU Director / Operations Director | X32: Key Account Manager
C33: 2.5 | D33: Design Concept Review | N33: 1.- Design Concept 2.- BOM (inside PDCC) 3.- Process Flowchart | S33: 1.- Design Concept: all mandatory fields fileld in (BOM and Flowchart) 2.- BOM & Process Flowchart in PDCC matching with Design Concept 3.- Process Flowchart defines all steps of the process (manufacturing and control) | T33: 1 &2 .- Product design engineer 3.- Process design engineer | U33: R&D Manager | V33: 1 &2.- Process design engineer 3.- Industrial engineer | W33: Category Design Leader | X33: Project Manager / Purchasing Manager / R&D Director
C34: 2.6 | D34: DFMEA and Preliminary PFMEA | N34: 1.- DFMEA 2.- PFMEA | S34: 1.- DFMEA is including all customer requirements and PFMEA is including all process steps and product characteristics 2.- There is always action when RPN is higher than defined limit (100) 3.- Both FMEAs are reviewed by Functional Manager and CDL | T34: 1. Product design Engineer 2. Process design Engineer | U34: Project Quality Engineer | V34: Coporate QMS / Field Application Engineer | W34: Corporate Quality Engineer / R&D Manager / Category Deisgn Leader / Engineering Manager | X34: Engineering Manager/ Production Manager/ Plant Quality Manager / Project Manager
C35: 2.7 | D35: Product & Process Technical Definition: | N35: 1. Product Datasheet and Raw material specifications 2. Process Specifications | S35: 1.- Product Datasheet and Raw material specifications: all mandatory fields are filled in and document is reviewed by RD Manager 2.- Process Specifications: all process steps in flow chart are included and full requirements of process are defined (controls, manufacturing parameters, technology to be used, cycle time and others) | T35: 1.- Product design engineer 2.- Process design Engineer | U35: R&D Manager | V35: Category Design Leader | W35: R&D Director | X35: KAM/ Engineering Manager / Project Manager / R&D Director / Corporate Quality System
C36: 2.8 | D36: Preliminary Control Plan | N36: Control Plan | S36: 1.- Control plan: all process steps, product and process characteristics are covered 2.- Control plan is reviewed by Corporate Quality Engineer, Engineering Manager and RD Manager | T36: Project Quality Engineer | U36: Corporate Quality Engineer | V36: Process design engineer / Industrial engineer | W36: R&D Manager / Engineering Manager | X36: Plant Quality Manager / Production Manager / Engineering Manager / R&D Manager
C37: 2.9 | D37: Preliminary Work Instruction | N37: Samples WI (B) | S37: 1.- All materials of BOM and process steps inside PDCC/Design Concept are included. Visuals are provided with pictures of real parts. 2.- Quality criteria and process parameters for each step and technology to be used is defined 3.- Reviewed by RD Supervisor/Manager | T37: Process Design Engineer | U37: R&D Manager | V37: Industrial Engineer / Manufacturing Engineer | W37: Prototype Engineer | X37: Prototype Engineer / Sample Leader / Project Quality Inspector
C38: 2.10 | D38: Qualification Test Plan (QTP) | N38: Qualification Test Plan | S38: 1.- All tests compliant to AECQ-200 and specific customer requirements are considered 2.- Timeline with quantities needed and planned dates for tests is available and can match planned schedule for the phase 3.- QTP plan is reviewed by Project Manager and QA Manager | T38: Project Quality | U38: QA Manager | V38: Product design Engineer / Category Design Leader | W38: Customer / Project Manager | X38: Project Manager Lab Engineer
C39: 2.11 | D39: DV Bundle (*) | N39: Close DV Bundle: 1. Raw material inspection report (all sources) 2. Process DOE results (all sources - fix parameters) 3. Limit tolerance check (max, nom, min, for all sources) 4. QTP report (all sources - fix parameters) | S39: 1.- All mandatory fields are filled in 2.- Manufacturability assessment result is pass (process DOE) 3.- Limit tolerance is fixed for each RM 4.- QTP report result is passed for all tolerances of at least one source for each RM | T39: 1. IQC inspector 2. Prototype Engineer 3. Process Designer 4. Lab. Engineer | U39: 1. Project Quality Engineer 2. Process Design Engineer 3. R&D Manager 4. Project Quality Engineer | V39: Corporate QMS / Corporate Quality Engineer / Category Design Leader | W39: R&D Director / QA Director | X39: Project Manager KAM
C40: 2.12 | D40: Product datasheet and process specifications | N40: 1.- Product datasheet and Raw material specifications 2.- BOM and Packaging Agreement 3.- Process specifications | S40: 1.- Product Datasheet and Raw material specifications: all mandatory fields are filled in and document is reviewed by RD Manager. Parameters should match with validated QTP results. 2.- BOM updated according with QTP results and Packaging agreed with customer 3.- Process Specifications: all process steps in flow chart are included and full requirements of process are defined (controls, manufacturing parameters, technology to be used, cycle time and others). Parameters should match with validated QTP results. | T40: 1 & 2.- Product design Engineer 3.- Process design Engineer | U40: R&D Manager | V40: Corporate QMS | W40: R&D Director / QA Director | X40: Project Manager
C41: 2.13 | D41: PFMEA | N41: PFMEA | S41: 1.- PFMEA is including all process steps and product characteristics 2.- There is always action when RPN is higher than defined limit (100) 3.- PFMEA is reviewed by Functional Manager and CDL | T41: Process Design Engineer | U41: Project Quality Engineer | V41: Industrial Engineer / Manufacturing Engineer | W41: Corporate Quality Engineer / R&D Manager / Category Deisgn Leader / Engineering Manager | X41: Engineering Manager/ Quailty Manager/ Production Manager / R&D Manager / Project Manager
... C44: 2.16 | D44: SOCO for Machine & Equipment (internal - no sourcing decision to supplier) (*) | N44: SOCO for Machine & Equipment (internal only - no sourcing decision to supplier) | S44: 1. Supplier Technical Feasibility vs Process specification is passed 2.- At least 3 quotes are presented and the quotation nominated is matching the target CAPEX in PDCC 3.- Cost breakdown is available for presented quotes 4.- Detailed timeline is available and complies with project timing requirements | T44: Industrial Engineer | U44: Engineering Manager | V44: Process design Engineer / Corporate controller | W44: Operations Director / Plant Manager | X44: Project Quality Engineer / Project Manager
C45: PHASE VALIDATION RESULT | G45: PHASE LEAD
...

Sheet Sheet1

Sheet Sheet2

Sheet 0. Items + RASIC
B3: APQP Gate Release Checklist (APQP GRC) | O3: GATES RASIC CHART RESPONSIBLE ACCOUNTABLE SUPPORTING INFORMED CONSULTED | U3: Open | V3: OK | W3: Automotive | Y3: TBD | AA3: TBD
U4: Conditionally closed | V4: Cond. OK | W4: Non-Automotive | Y4: PREMO Mediterranée | AA4: Da Nang
V5: N/A | Y5: PREMO Wuhu | AA5: Málaga
G6: Project Manager : | L6: Project Name: | AA6: Tangier
G7: PREMO P/N: | L7: Part Description: | AA7: Wuhu
G8: Customer P/N: | L8: Customer Name:
G9: Samples Center: | L9: Category:
G10: Manuf. Center: | L10: Last Rev. Date:
B12: 1 | C12: FEASIBILITY FOR OPPORTUNITIES - PHASE LEAD: BU DIRECTOR | N12: Action item/Deliverable | O12: Responsible | P12: Accountable | Q12: Supporting | R12: Informed | S12: Consulted
B13: Feasibility for Opportunities | C13: 1.1 | D13: CIR (Customer Input Requirements) | N13: CIR Form (Technical/Commercial) | O13: Key Account Manager | P13: BU Director | Q13: Field Application Engineer | R13: R&D Director / Corporate Quality Director | S13: Category Design Leader
C14: 1.2 | D14: Technical Feasibility | N14: Technical Feasibility Analysis | O14: Field Application Engineer | P14: Key Account Manager | Q14: Product design engineer / Corporate controller | R14: BU Director | S14: Category Design Leader
C15: 1.3 | D15: Project Committee Acceptance | N15: 1.- Project Cttee Acceptance Submission 2.- Gate 1 Release Team definition and design/samples/manuf center definition inside PCA submission | O15: 1.- Key Account Manager 2.- RD Director, Purchasing Director, Quality Director, Plant Manager, Operations Director | P15: BU Director | Q15: Field Application Engineer | R15: CFO / Sr. Management Team / Project Manager | S15: CEO
C16: 1.4 | D16: Previous DFMEA and Lessons Learnt | N16: DFMEA and Lessons Learn up to date of the product family | O16: Field Application Engineer | P16: R&D Manager | Q16: Category Design Leader | R16: Corporate Quality Director | S16: Project Quality Engineer
C17: 1.5 | D17: Technical definition | O17: Product design engineer | P17: Field Application Engineer | Q17: Process design engineer | R17: R&D Director / Key Account Manager / Purchasing Officer / Project Quality Engineer | S17: Category Design Leader
C18: 1.6 | D18: PDCC completion | N18: PDCC | O18: PDCC team defined inside PDCC | P18: Key Account Manager | Q18: Field Application Engineer | R18: Corporate Controller / BU Director | S18: Corporate Controller
C19: 1.7 | D19: Samples WI | N19: Samples WI (A) | O19: Product design Engineer | P19: R&D Manager | Q19: Process design Engineer | R19: Field Application Engineer | S19: Prototype Engineer
C20: 1.8 | D20: Sample Production | N20: 1. Sample Production Plan 2. SIR | O20: 1.- Product design engineer 2.- Prototype Engineer | P20: 1.- Field Application Engineer 2.- Product design engineer | Q20: Process design Engineer | R20: Field Application Engineer | S20: R&D Manager
C21: 1.9 | D21: Customer Feedback | N21: Customer feedback: Email, report summary | O21: Key Account Manager | P21: BU Director | Q21: Category Design Leader / Field Application Engineer | R21: R&D Manager | S21: Product design engineer
C22: 1.10 | D22: Feasibility bundle (*) | N22: Close Feasibility Bundle (project plan inside) | O22: Project Manager | P22: Key Account Manager | Q22: R&D Manager | R22: BU Director / Plant Manager | S22: R&D Director / Plant Manager
C23: 1.11 | D23: Customer Agreement - LON (*) | N23: 1.- RFQ Cttee Submission 2.- LON | O23: Key Account Manager | P23: BU Director | Q23: Project Manager | R23: Sr. Management Team / Project Manager | S23: Corporate Controller
C24: PHASE VALIDATION RESULT | G24: PHASE LEAD
C25: Release Status: | E25: Not started | G25: BU Director
C26: Released by:
C27: Release Date:
B28: 2 | C28: DESIGN VALIDATION - PHASE LEAD: CORP. RD DIRECTOR | N28: Action item/Deliverable | O28: Responsible | P28: Accountable | Q28: Supporting | R28: Informed | S28: Consulted
B29: Design Validation | C29: 2.1 | D29: Team Definition | N29: Gate Release Team defined in GRC Form and in PDCC for all the gates (adding 2, 3 and 4) | O29: Project Manager | P29: Plant Manager | Q29: R&D Manager / QA Manager / Engineering Manager / Purchasing Manager / Production Manager/ Maintenance Manager / Supply Chain Manager | R29: Sr. Management Team / Plant Management Team | S29: Operations Director / R&D Director / QA Director / Purchasing Director
C30: 2.2 | D30: Project Master Plan | N30: PMP (Project Master Plan): 1. DV 2. PV 3. QTP 4. Supplier validation 5. Customer milestones vs Premo milestones | O30: 1. Product design Engineer 2. Industrial Engineer 3. Project Quality Engineer 4. Purchasing Officer | P30: Project Manager | Q30: 1.- Field Application Engineer 2.- Process design Engineer 3.- Laboratory Engineer 4.- Supplier Quality Engineer | R30: R&D Director / BU Director / QA Director / Purchasing Director / Plant Manager / Key Account Manager | S30: 1. R&D Manager 2. Engineering Manager 3. QA Manager 4. Purchasing Manager 5.- Key Account Manager
C31: 2.3 | D31: Launch the investment | N31: 1.- CAPEX Cttee Submission 2.- Investment system release | O31: 1.- Project Manager 2.- Corporate controller | P31: 1.- RD Director 2.- Project Manager | Q31: Quality Director / Purchasing Director / R&D Director | R31: Purchasing Manager / Quality Manager / Plant Finance Manager / Plant Manager | S31: CEO / CFO
C32: 2.4 | D32: Project Kick off | N32: Email or MoM | O32: Project Manager | P32: Plant Manager | Q32: R&D Manager / QA Manager / Engineering Manager / Purchasing Manager / Production Manager/ Maintenance Manager / Supply Chain Manager | R32: Key Account Manager | S32: BU Director / Operations Director
C33: 2.5 | D33: Design Concept Review | N33: 1.- Design Concept 2.- BOM (inside PDCC) 3.- Process Flowchart | O33: 1 &2 .- Product design engineer 3.- Process design engineer | P33: R&D Manager | Q33: 1 &2.- Process design engineer 3.- Industrial engineer | R33: Project Manager / Purchasing Manager / R&D Director | S33: Category Design Leader
C34: 2.6 | D34: DFMEA and Preliminary PFMEA | N34: 1.- DFMEA 2.- PFMEA | O34: 1. Product design Engineer 2. Process design Engineer | P34: Project Quality Engineer | Q34: Coporate QMS / Field Application Engineer | R34: Engineering Manager/ Production Manager/ Plant Quality Manager / Project Manager | S34: Corporate Quality Engineer / R&D Manager / Category Deisgn Leader / Engineering Manager
C35: 2.7 | D35: Product & Process Technical Definition: | N35: 1. Product Datasheet and Raw material specifications 2. Process Specifications | O35: 1.- Product design engineer 2.- Process design Engineer | P35: R&D Manager | Q35: Category Design Leader | R35: KAM/ Engineering Manager / Project Manager / R&D Director / Corporate QMS | S35: R&D Director
C36: 2.8 | D36: Preliminary Control Plan | N36: Control Plan | O36: Project Quality Engineer | P36: Corporate Quality Engineer | Q36: Process design engineer / Industrial engineer | R36: Plant Quality Manager / Production Manager / Engineering Manager / R&D Manager | S36: R&D Manager / Engineering Manager
C37: 2.9 | D37: Preliminary Work Instruction | N37: Samples WI (B) | O37: Process Design Engineer | P37: R&D Manager | Q37: Industrial Engineer / Manufacturing Engineer | R37: Prototype Engineer | S37: Prototype Engineer
C38: 2.10 | D38: Qualification Test Plan (QTP) | N38: Qualification Test Plan | O38: Project Quality | P38: QA Manager | Q38: Product design Engineer / Category Design Leader | R38: Project Manager Lab Engineer | S38: Customer / Project Manager
C39: 2.11 | D39: DV Bundle (*) | N39: Close DV Bundle: 1. Raw material inspection report (all sources) 2. Process DOE results (all sources - fix parameters) 3. Limit tolerance check (max, nom, min, for all sources) 4. QTP report (all sources - fix parameters) | O39: 1. Lab. Engineer / IQC inspector 2. Prototype Engineer 3. Process Designer 4. Lab. Engineer | P39: 1. Project Quality Engineer 2. Process Design Engineer 3. R&D Manager 4. Project Quality Engineer | Q39: Corporate QMS / Corporate Quality Engineer / Category Design Leader | R39: Project Manager Key Account Manager | S39: R&D Director / QA Director
C40: 2.12 | D40: Product datasheet and process specifications | N40: 1.- Product datasheet and Raw material specifications 2.- BOM and Packaging Agreement 3.- Process specifications | O40: 1 & 2.- Product design Engineer 3.- Process design Engineer | P40: R&D Manager | Q40: Corporate QMS | R40: Project Manager | S40: R&D Director / QA Director
C41: 2.13 | D41: PFMEA | N41: PFMEA | O41: Process Design Engineer | P41: Project Quality Engineer | Q41: Industrial Engineer / Manufacturing Engineer | R41: Engineering Manager/ Quailty Manager/ Production Manager / R&D Manager / Project Manager | S41: Corporate Quality Engineer / R&D Manager / Category Deisgn Leader / Engineering Manager
... C44: 2.16 | D44: SOCO for Machine & Equipment (internal - no sourcing decision to supplier) (*) | N44: SOCO for Machine & Equipment (internal only - no sourcing decision to supplier) | O44: Industrial Engineer | P44: Engineering Manager | Q44: Process design Engineer / Corporate controller | R44: Project Quality Engineer / Project Manager | S44: Operations Director / Plant Manager
C45: PHASE VALIDATION RESULT | G45: PHASE LEAD
...

Sheet 1. Feasibility
B3: APQP Gate Release Checklist (APQP GRC) FEASIBILITY FOR OPPORTUNITIES - PHASE LEAD: BU DIRECTOR | Q3: Pending | R3: Open | S3: OK | T3: Automotive | V3: TBD | X3: TBD
Q4: WIP | R4: Conditionally closed | S4: Cond. OK | T4: Non-Automotive | V4: PREMO Mediterranée | X4: Da Nang | Y4: Open
Q5: Done | S5: N/A | V5: PREMO Wuhu | X5: Málaga | Y5: Closed
I6: Project Manager : | J6: =_xlfn.CONCAT('0.APQP GRC'!D6:F6) -> Name Surname | L6: Project Name: | N6: =_xlfn.CONCAT('0.APQP GRC'!H6,) | Q6: Reviewed | X6: Tangier
I7: PREMO P/N: | J7: =_xlfn.CONCAT('0.APQP GRC'!D7:F7) -> X-12345-678 | L7: Part Description: | N7: =_xlfn.CONCAT('0.APQP GRC'!H7,) | Q7: Approved | X7: Wuhu
I8: Customer P/N: | J8: =_xlfn.CONCAT('0.APQP GRC'!D8:F8) -> RT23423AA | L8: º | N8: =_xlfn.CONCAT('0.APQP GRC'!H8,) -> Name of the customer | Q8: Rejected
I9: Samples Center: | J9: =_xlfn.CONCAT('0.APQP GRC'!D9:F9) | L9: Category: | N9: =_xlfn.CONCAT('0.APQP GRC'!H9,)
I10: Manuf. Center: | J10: =_xlfn.CONCAT('0.APQP GRC'!D10:F10) | L10: Last Rev. Date: | N10: =_xlfn.CONCAT('0.APQP GRC'!H10,)
B12: 1 | C12: # | D12: Gate | J12: Action item/Deliverable | K12: Status | L12: Planned Date | M12: Closed Date | N12: Link to deliverable | O12: Remarks / Gaps | P12: Criteria for acceptance
B13: Feasibility for Opportunities | C13: 1.1 | D13: CIR (Customer Input Requirements) | J13: CIR Form (Technical/Commercial) | K13: Pending | P13: 1.- All mandatory fields filled in 2.- Reviewed by BU Director
C14: 1.2 | D14: Technical Feasibility | J14: Technical Feasibility Analysis | K14: Pending | P14: 1.- Technical feasibility analysis result is determined (OK/NG): product/process requirements cross check and estimated margin (quick costing done) 2.- Reviewed by CDL
C15: 1.3 | D15: Project Committe Acceptance | J15: 1.- Project Cttee Acceptance Submission 2.- Gate 1 Release Team definition and design/samples/manuf center definition inside PCA submission | K15: Pending | P15: 1.- Technical feasibility analysis result must be OK 2.- All mandatory fields filled in 3.- Reviewed by CDL
C16: 1.4 | D16: Previous DFMEA and Lessons Learnt | J16: DFMEA and Lessons Learn up to date of the product family | K16: Pending | P16: 1.- Family FMEA is reviewed by FAE
C17: 1.5 | D17: Technical definition | J17: 1. Design Concept 2. BOM & Process Flowchart (inside PDCC) 3. Preliminary Datasheet | K17: Pending | P17: 1.- Design Concept: all mandatory fields fileld in (BOM and Flowchart) 2.- BOM & Process Flowchart in PDCC matching with Design Concept 3.- Preliminary Datasheet is complete and reviewed by RD Manager/Supervisor/CDL
C18: 1.6 | D18: PDCC completion | J18: PDCC | K18: Pending | P18: 1.- All mandatory fields filled in 2.- Reviewed by Functional Managers (Purchasing, RD) 3.- Reviewed by Corporate controlling for consistency
C19: 1.7 | D19: Samples WI | J19: Samples WI (A) | K19: Pending | P19: 1.- All materials of BOM and process steps inside PDCC/Design Concept are included. Visuals may be provided with 3D drawing snapshots at this stage. 2.- Quality criteria for each step and technology to be used is defined. No need to specify process parameters, only record them in SIR later. 3.- Reviewed by RD Supervisor/Manager
C20: 1.8 | D20: Sample Production | J20: 1. Sample Production Plan 2. SIR | K20: Pending | P20: 1.- Sample Production Plan: all mandatory fields are filled in and reviewed by FAE/RD Manager 2.- SIR: all mandatory fields are filled in (including 3rd and extreme test/disassembly) and reviewed by Product design engineer
C21: 1.9 | D21: Customer Feedback | J21: Customer feedback: Email, report summary | K21: Pending | P21: Evidence is available
C22: 1.10 | D22: Feasibility bundle (*) | J22: Close Feasibility Bundle (project plan inside) | K22: Pending | P22: 1.- Close Feasibility Bundle result is determined (OK/NG) based on timeline, pricing and technical feasibility by customer. Includes Logistics Protocol. 2.- Close Feasibility Bundle is reviewed by senior management team (RD Director/QA Director/Plant Manager/Purchasing Director)
C23: 1.11 | D23: Customer Agreement - LON (*) | J23: 1.- RFQ Cttee Submission 2.- LON | K23: Pending | P23: 1.- Close Feasibility Bundle result is OK from customer and internal review. 2.- RFQ Cttee Submission conditions match with LON conditions 3.- LON is reviewed by Corporate Controlling 4.- LON is signed by CFO/CEO
C24: PHASE VALIDATION RESULT | G24: PHASE LEAD
C25: Release Status: | E25: Not started | G25: BU Director
C26: Released by:
C27: Release Date:
C29: ACTIONS TO DO IN CASE OF CONDITIONAL APPROVAL
C30: # | D30: RESPONSIBLE | F30: DUE DATE | G30: CLOSE DATE | H30: STATUS | I30: DESCRIPTION
C31: 1
C32: 2
C33: 3
C34: 4
C35: 5
C36: 6
C37: 7
C38: 8
C39: 9
C40: 10

Sheet 2.Design Validation
B3: APQP Gate Release Checklist (APQP GRC) DESIGN VALIDATION - PHASE LEAD: CORP RD DIRECTOR | Q3: Open | R3: OK | S3: Automotive | U3: TBD | W3: TBD
Q4: Conditionally closed | R4: Cond. OK | S4: Non-Automotive | U4: PREMO Mediterranée | W4: Da Nang
R5: N/A | U5: PREMO Wuhu | W5: Málaga
H6: Project Manager : | I6: =_xlfn.CONCAT('0.APQP GRC'!D6:F6) -> Name Surname | K6: Project Name: | M6: =_xlfn.CONCAT('0.APQP GRC'!H6,) | W6: Tangier
H7: PREMO P/N: | I7: =_xlfn.CONCAT('0.APQP GRC'!D7:F7) -> X-12345-678 | K7: Part Description: | M7: =_xlfn.CONCAT('0.APQP GRC'!H7,) | W7: Wuhu
H8: Customer P/N: | I8: =_xlfn.CONCAT('0.APQP GRC'!D8:F8) -> RT23423AA | K8: º | M8: =_xlfn.CONCAT('0.APQP GRC'!H8,) -> Name of the customer
H9: Samples Center: | I9: =_xlfn.CONCAT('0.APQP GRC'!D9:F9) | K9: Category: | M9: =_xlfn.CONCAT('0.APQP GRC'!H9,)
H10: Manuf. Center: | I10: =_xlfn.CONCAT('0.APQP GRC'!D10:F10) | K10: Last Rev. Date: | M10: =_xlfn.CONCAT('0.APQP GRC'!H10,)
B12: 2 | C12: # | D12: Gate | I12: Action item/Deliverable | J12: Status | K12: Planned Date | L12: Closed Date | M12: Link to deliverable | N12: Remarks / Gaps | O12: Criteria for acceptance
B13: Design Validation | C13: 2.1 | D13: Team Definition | I13: Gate Release Team defined in GRC Form and in PDCC for all the gates (adding 2, 3 and 4) | J13: Pending | O13: 1.- Gate Release Team for all gates defined (adding 2, 3 and 4) 2.- Team definition coordinated with functions and communicated to responsibles and management
C14: 2.2 | D14: Project Master Plan | I14: PMP (Project Master Plan): 1. DV 2. PV 3. QTP 4. Supplier validation 5. Customer milestones vs Premo milestones | J14: Pending | O14: 1.- All plans are available 2.- Customer milestones are achievable 3.- Plans are reviewed by Functional managers
C15: 2.3 | D15: Launch the investment | I15: 1.- CAPEX Cttee Submission 2.- Investment system release | J15: Pending | O15: 1.- CAPEX Cttee Submission: all mandatory data is filled in (project introduction, technical presentation, investment list, economical analysis) and is presented in Monthly CAPEX meeting to Senior Mgmt 2.- Investment system release: CAPEX Cttee Submission is approved by CEO and CFO and CO order released for the approved amount
C16: 2.4 | D16: Project Kick off | I16: Email or MoM | J16: Pending | O16: MoM is available
C17: 2.5 | D17: Design Concept Review | I17: 1.- Design Concept 2.- BOM (inside PDCC) 3.- Process Flowchart | J17: Pending | O17: 1.- Design Concept: all mandatory fields fileld in (BOM and Flowchart) 2.- BOM & Process Flowchart in PDCC matching with Design Concept 3.- Process Flowchart defines all steps of the process (manufacturing and control)
C18: 2.6 | D18: DFMEA and Preliminary PFMEA | I18: 1.- DFMEA 2.- PFMEA | J18: Pending | O18: 1.The DFMEA includes all customer requirements, and the PFMEA includes all process steps and product characteristics, integrating poka‑yoke concepts to prevent potential errors at the source. 2.Actions are implemented based on the assigned Action Priority (AP): – For AP High, the team must define and implement actions to improve prevention and/or detection controls, prioritizing poka‑yoke solutions when feasible. – For AP Medium, the team should identify appropriate actions or formally justify why existing controls are adequate. – For AP Low, the team may consider additional improvements when beneficial. 3.Both FMEAs are reviewed by the Functional Manager and CDL, ensuring that all risk‑reduction measures, including applicable poka‑yoke mechanisms, are properly assessed and validated.
C19: 2.7 | D19: Product & Process Technical Definition: | I19: 1. Product Datasheet and Raw material specifications 2. Process Specifications | J19: Pending | O19: 1.- Product Datasheet and Raw material specifications: all mandatory fields are filled in and document is reviewed by RD Manager 2.- Process Specifications: all process steps in flow chart are included and full requirements of process are defined (controls, manufacturing parameters, technology to be used, cycle time and others)
C20: 2.8 | D20: Preliminary Control Plan | I20: Control Plan | J20: Pending | O20: 1.- Control plan: all process steps, product and process characteristics are covered 2.- Control plan is reviewed by Corporate Quality Engineer, Engineering Manager and RD Manager
C21: 2.9 | D21: Preliminary Work Instruction | I21: Samples WI (B) | J21: Pending | O21: 1.- All materials of BOM and process steps inside PDCC/Design Concept are included. Visuals are provided with pictures of real parts. 2.- Quality criteria and process parameters for each step and technology to be used is defined 3.- Reviewed by RD Supervisor/Manager
C22: 2.10 | D22: Qualification Test Plan (QTP) | I22: Qualification Test Plan | J22: Pending | O22: 1.- All tests compliant to AECQ-200 and specific customer requirements are considered 2.- Timeline with quantities needed and planned dates for tests is available and can match planned schedule for the phase 3.- QTP plan is reviewed by Project Manager and QA Manager
C23: 2.11 | D23: DV Bundle (*) | I23: Close DV Bundle: 1. Raw material inspection report (all sources) 2. Process DOE results (all sources - fix parameters) 3. Limit tolerance check (max, nom, min, for all sources) 4. QTP report (all sources - fix parameters) | J23: Pending | O23: 1.- All mandatory fields are filled in 2.- Manufacturability assessment result is pass (process DOE) 3.- Limit tolerance is fixed for each RM 4.- QTP report result is passed for all tolerances of at least one source for each RM
C24: 2.12 | D24: Product datasheet and process specifications | I24: 1.- Product datasheet and Raw material specifications 2.- BOM and Packaging Agreement 3.- Process specifications | J24: Pending | O24: 1.- Product Datasheet and Raw material specifications: all mandatory fields are filled in and document is reviewed by RD Manager. Parameters should match with validated QTP results. 2.- BOM updated according with QTP results and Packaging agreed with customer 3.- Process Specifications: all process steps in flow chart are included and full requirements of process are defined (controls, manufacturing parameters, technology to be used, cycle time and others). Parameters should match with validated QTP results.
C25: 2.13 | D25: PFMEA | I25: PFMEA | J25: Pending | O25: 1.- PFMEA is including all process steps and product characteristics 2.- There is always action when RPN is higher than defined limit (100) 3.- PFMEA is reviewed by Functional Manager and CDL
... C28: 2.16 | D28: SOCO for Machine & Equipment (internal - no sourcing decision to supplier) (*) | I28: SOCO for Machine & Equipment (internal only - no sourcing decision to supplier) | J28: Pending | O28: 1. Supplier Technical Feasibility vs Process specification is passed 2.- At least 3 quotes are presented and the quotation nominated is matching the target CAPEX in PDCC 3.- Cost breakdown is available for presented quotes 4.- Detailed timeline is available and complies with project timing requirements
C29: PHASE VALIDATION RESULT | G29: PHASE LEAD
C30: Release Status: | E30: Not started | G30: RD Director
C31: Released by:
C32: Release Date:
C34: ACTIONS TO DO IN CASE OF CONDITIONAL APPROVAL
C35: # | D35: RESPONSIBLE | F35: DUE DATE | G35: CLOSE DATE | H35: STATUS | I35: DESCRIPTION
C36: 1
C37: 2
C38: 3
C39: 4
C40: 5
C41: 6
C42: 7
C43: 8
C44: 9
C45: 10

Sheet 3. Industrialization
B3: APQP Gate Release Checklist (APQP GRC) INDUSTRIALIZATION - PHASE LEAD: PLANT MANAGER | Q3: Open | R3: OK | S3: Automotive | U3: TBD | W3: TBD
Q4: Conditionally closed | R4: Cond. OK | S4: Non-Automotive | U4: PREMO Mediterranée | W4: Da Nang
R5: N/A | U5: PREMO Wuhu | W5: Málaga
H6: Project Manager : | I6: =_xlfn.CONCAT('0.APQP GRC'!D6:F6) -> Name Surname | K6: Project Name: | M6: =_xlfn.CONCAT('0.APQP GRC'!H6,) | W6: Tangier
H7: PREMO P/N: | I7: =_xlfn.CONCAT('0.APQP GRC'!D7:F7) -> X-12345-678 | K7: Part Description: | M7: =_xlfn.CONCAT('0.APQP GRC'!H7,) | W7: Wuhu
H8: Customer P/N: | I8: =_xlfn.CONCAT('0.APQP GRC'!D8:F8) -> RT23423AA | K8: º | M8: =_xlfn.CONCAT('0.APQP GRC'!H8,) -> Name of the customer
H9: Samples Center: | I9: =_xlfn.CONCAT('0.APQP GRC'!D9:F9) | K9: Category: | M9: =_xlfn.CONCAT('0.APQP GRC'!H9,)
H10: Manuf. Center: | I10: =_xlfn.CONCAT('0.APQP GRC'!D10:F10) | K10: Last Rev. Date: | M10: =_xlfn.CONCAT('0.APQP GRC'!H10,)
B12: 3 | C12: # | D12: Gate | I12: Action item/Deliverable | J12: Status | K12: Planned Date | L12: Closed Date | M12: Link to deliverable | N12: Remarks / Gaps | O12: Criteria for acceptance
B13: Industrialization | C13: 3.1 | D13: Launch the investment | I13: 1.- CAPEX Ctte Submission 2.- Investment system release | J13: Pending | O13: 1.- CAPEX Cttee Submission: all mandatory data is filled in (project introduction, technical presentation, investment list, economical analysis) and is presented in Monthly CAPEX meeting to Senior Mgmt 2.- Investment system release: CAPEX Cttee Submission is approved by CEO and CFO and CO order released for the approved amount
C14: 3.2 | D14: Definitve Production Layout | I14: Full Operating Layout | J14: Pending | O14: 1.- All machines, equipments and accessories of the line are depicted in the production layout and consistent with the process flow chart. 2.- All material movements are depicted in the layout and consistent with the process flow chart. 3.- All direct employees operating the line are depicted in the layout and consistent with the process flow chart. 4.- Full Operating Layout is reviewed by Plant Manager
C15: 3.3 | D15: Equipment installation | I15: 1.- FAT Report 2.- Installation checklist | J15: Pending | O15: 1.- FAT Report: all mandatory fields are filled in (machinery construction and assembly is fully completed and all functions implemented) and reviewed by Engineering Manager 2.- Installation checklist: all mandatory fields are filled in (neumatics, electricity, oil and other installations completed successfully) and reviewed by Facility/Engineering Manager
C16: 3.4 | D16: Raw Material approved (PPAP) & Capacity Verification (Run@Rate) | I16: RM PPAP approved (all suppliers) | J16: Pending | O16: 1.- Run and Rate's score is passed vs PDCC requested capacity 2.- QTP in DV passed for the material (DV Bundle) 3.- Control plan from supplier is audited and approved by Premo 4.- Supplier datasheet matching with Premo RM Specification and reviewed and approved by Premo
C17: 3.5 | D17: Material Reception & Delivery | I17: 1. WI for Packaging (FGs in pallets) / shipment preparation (Family) 2. WI for Storage (Family) 3. WI for Incoming Inspection 4. Tools for incoming inspection | J17: Pending | O17: 1.- WI for Packaging: Family WI is updated and reviewed by Supply Chain Manager 2.- WI for Storage: Family WI is updated and reviewed by Supply Chain Manager 3.- WI for Incoming Inspection: all special characteristics in RM Specification are mentioned and controlled with proper equipment and reviewed by QA Manager
C18: 3.6 | D18: IQ (Installation Qualification) | I18: IQ Bundle | J18: Pending | O18: 1.- Pre-installation verification: overall inspection without damages/abnormalities, no missing components 2.- Installation verification: power on/off, basic setup check, components/equipments status 3.- Functional verification: all features present and working, worst case check
C19: 3.7 | D19: OQ (Operation Qualification) | I19: OQ Bundle: 1. Setup Work Instructions & records 2. Spare part list 3. Preventive Maintenance Plan and WI 4. Machine R@R | J19: Pending | O19: 1.- Setup Work Instructions & records: all steps to setup the machine are mentioned and well documented and reviewed by Maintenance Manager 2.- Spare part list: all needed spare parts are listed and reviewed by Maintenance Manager 3.- Preventive Maintenance Plan and WI: all items that are needed are mentioned and reviewed with Maintenance Manager 4.- Machine R@R: result of OEE pass versus defined PDCC target and reviewed by Engineering Manager
C20: 3.8 | D20: PQ (Performance Qualification) | I20: PQ Bundle: 1.- Machine setup and DOE 2. MSA (all stations GO/NG, fixed process parameters) 3. Gage R&R (all manufacturing processes and test processes with numerical result, fixed process parameters) | J20: Pending | O20: 1.- MSA (all stations GO/NG, fixed process parameters): result is pass. 2.- Gage R&R (all manufacturing processes and test processes with numerical result, fixed process parameters): result is pass.
C21: 3.9 | D21: Definitive Process Documentation | I21: 1. PFMEA 2. Control Plan | J21: Pending | O21: 1.- PFMEA is including all process steps and product characteristics 2.- There is always action when RPN is higher than defined limit (100) 3.- PFMEA is reviewed by Functional Manager and CDL 4.- Control plan: all process steps, product and process characteristics are covered 5.- Control plan is reviewed by Quality Manager, Engineering Manager and Production Manager
C22: 3.10 | D22: Wis and Training | I22: 1. Manufacturing Work Instructions 2. Training Plan and Training Matrix (Production / Quality) | J22: Pending | O22: 1.- All materials of BOM and process steps inside PDCC/Design Concept are included. Visuals are provided with pictures of real parts. 2.- Quality criteria and process parameters for each step and technology to be used is defined. Visuals of NG and Good parts are clearly defined with pictures of real parts. 3.- The set of toolings and parameters to operate each station is clearly defined and aligned with control plan, stablishing a 6S standard for compliance 4.- The sequence of operation in each station of the process is defined in detail and with supportive pictures to let operator understand (specially in manual stations) 5.- Reviewed by Production Manager
C23: 3.11 | D23: Line Release Audit - Including New Equipment, Tooling, and Test Equipment Release (*) | I23: Line Release Report: 1. Run @ Rate 2. Process Audit (VDA 6.3) 3. Closing Meeting (Line Release Report should be available) 4. Action plan approval and launch (2 weeks max timing) | J23: Pending | O23: 1.- Run & Rate result is pass 2.- Process Audit result is pass 3.- Line Release Report is signed by Plant Manager and agreed by all Functional managers in the plant
C24: 3.12 | D24: QTP batch manufacturing with full conditions | I24: 1. QTP batch manufacturing 2. QTP test 3. QTP Report | J24: Pending | O24: 1.- QTP Report result is pass 2.- QTP Report is containing all test results from the tests highlighted in QTP plan 3.- QTP Report contains pictures and measurements of the real parts for each test and the parts are physically available for inspection if requested
C25: 3.13 | D25: FMEA and Control Plan final review and release | I25: 1. PFMEA 2. Control Plan | J25: Pending | O25: 1.- PFMEA is including all process steps and product characteristics 2.- There is always action when RPN is higher than defined limit (100) 3.- PFMEA is reviewed by Functional Manager and CDL 4.- Control plan: all process steps, product and process characteristics are covered 5.- Control plan is reviewed by Quality Manager, Engineering Manager and Production Manager
... C27: 3.15 | D27: PPAP Approval (PSW Signed) - Received & Reviewed (*) | I27: PPAP | J27: Pending | O27: 1.- PPAP is approved by customer 2.- PPAP is reviewed by all Functional Managers 3.- PPAP is signed by Plant Manager/QA Director
C28: PHASE VALIDATION RESULT | G28: PHASE LEAD
C29: Release Status: | E29: Not started | G29: Plant Manager
C30: Released by:
C31: Release Date:
C33: ACTIONS TO DO IN CASE OF CONDITIONAL APPROVAL
C34: # | D34: RESPONSIBLE | F34: DUE DATE | G34: CLOSE DATE | H34: STATUS | I34: DESCRIPTION
C35: 1
C36: 2
C37: 3
C38: 4
C39: 5
C40: 6
C41: 7
C42: 8
C43: 9
C44: 10

Sheet 4. SOP+6M
B3: APQP Gate Release Checklist (APQP GRC) SOP + 6 MONTHS - PHASE LEAD: PROJECT MANAGER | U3: Open | V3: OK | W3: Automotive | Y3: TBD | AA3: TBD
U4: Conditionally closed | V4: Cond. OK | W4: Non-Automotive | Y4: PREMO Mediterranée | AA4: Da Nang
V5: N/A | Y5: PREMO Wuhu | AA5: Málaga
G6: Project Manager : | H6: =_xlfn.CONCAT('0.APQP GRC'!D6:F6) -> Name Surname | M6: Project Name: | N6: =_xlfn.CONCAT('0.APQP GRC'!H6,) | AA6: Tangier
G7: PREMO P/N: | H7: =_xlfn.CONCAT('0.APQP GRC'!D7:F7) -> X-12345-678 | M7: Part Description: | N7: =_xlfn.CONCAT('0.APQP GRC'!H7,) | AA7: Wuhu
G8: Customer P/N: | H8: =_xlfn.CONCAT('0.APQP GRC'!D8:F8) -> RT23423AA | M8: º | N8: =_xlfn.CONCAT('0.APQP GRC'!H8,) -> Name of the customer
G9: Samples Center: | H9: =_xlfn.CONCAT('0.APQP GRC'!D9:F9) | M9: Category: | N9: =_xlfn.CONCAT('0.APQP GRC'!H9,)
G10: Manuf. Center: | H10: =_xlfn.CONCAT('0.APQP GRC'!D10:F10) | M10: Last Rev. Date: | N10: =_xlfn.CONCAT('0.APQP GRC'!H10,)
B12: 4 | C12: # | D12: Gate | M12: Action item/Deliverable | N12: Status | O12: Planned Date | P12: Closed Date | Q12: Link to deliverable | R12: Remarks / Gaps | S12: Criteria for acceptance
B13: SOP + 6 Months | C13: 4.1 | D13: Quality Review (*) | M13: SOP Review format (Int/Ext Claims, Safe launch/Quality walls, Achievement vs LON, Deliveries vs orders, Actual profitability vs PDCC) | N13: Pending | S13: 1.- No claims in 6 months after project start or in a period of 6 months from last claim received 2.- Achievement matches with LON and deliveries are done according to orders without delay 3.- CM in PDCC matches CM in RFQ PDCC
C14: 4.2 | D14: Commercial Review (*) | N14: Pending
C15: 4.3 | D15: Profitability Review (*) | N15: Pending
C16: PHASE VALIDATION RESULT | G16: PHASE LEAD
C17: Release Status: | E17: Not started | G17: Project Manager
C18: Released by:
C19: Release Date:
C21: ACTIONS TO DO IN CASE OF CONDITIONAL APPROVAL
C22: # | D22: RESPONSIBLE | F22: DUE DATE | G22: CLOSE DATE | H22: STATUS | I22: DESCRIPTION
C23: 1
C24: 2
C25: 3
C26: 4
C27: 5
C28: 6
C29: 7
C30: 8
C31: 9
C32: 10

Sheet Gate Release Team
B2: Gate Release Team
B3: QG1 | C3: KAM | F3: Open | G3: OK | H3: Automotive | J3: TBD | L3: TBD
C4: BU Director | F4: Conditionally closed | G4: Cond. OK | H4: Non-Automotive | J4: PREMO Mediterranée | L4: Da Nang
C5: CDL | G5: N/A | J5: PREMO Wuhu | L5: Málaga
C6: FAE | L6: Tangier
C7: Product design Engineer | L7: Wuhu
C8: Process design Engineer
C9: Prototype Engineer
C10: RD Manager
C11: Project Quality Engineer
C12: Purchasing Officer
C13: Corporate controller
C14: Project Manager
C15: Plant Manager
C16: Project Quality Inspector
C17: Samples leader/operator
C18: Project Manager
B19: QG2 | C19: Industrial Engineer
C20: Engineering Manager
C21: Quality Manager
C22: Purchasing Manager
C23: Maintenance Manager
C24: Supply Chain Manager
C25: Finance Manager
C26: Corporate QMS
C27: Manufacturing Engineer
C28: Production Manager
C29: Corporate Quality Engineer
C30: Lab Engineer
C31: IQC inspector
C32: Supplier Quality Engineer
B33: QG3 | C33: Facilities Manager
C34: Quality System Engineer
C35: HSE supervisor
C36: Quality Supervisor
C37: Quality Control Engineer
C38: Production Supervisor
C39: Warehouse supervisor
C40: Maintenance engineer
C41: HR Supervisor
...

Sheet Ed. Control
A1: REVISION HISTORY
A3: Rev. | B3: Date | C3: Modification | D3: Made by | E3: Checked by | F3: Approved by
A4: 01 | B4: 45477 | C4: Initial version of the document | D4: Yogeshkumar L. | E4: J.Muñoz | F4: J.M. Pichot
A5: 02 | B5: 45518 | C5: Requirements reviewed. Format update. Added Possible requirements and evidences column. Added Remarks/Gaps column. Name updated to APQP GRC | D5: J.Muñoz | E5: O.Gutiérrez | F5: Yogeshkumar L.
A6: 03 | B6: 45586 | C6: General update of the checklist | D6: J.Muñoz | E6: O.Gutiérrez | F6: Yogeshkumar L.
A7: 04 | B7: 45621 | C7: Added "Responsible" and "Evidence" columns. Note in the header updated. "Design No" updated to Spec edition". "Review date" moved below "Reviewed by". ST2 Item 5 abd ST4 item 12 description updated. | D7: J.Muñoz | E7: O.Gutiérrez | F7: Yogeshkumar L.
A8: 05 | B8: 45639 | C8: "Responsibles" column updated | D8: J.Muñoz | E8: O.Gutiérrez | F8: Yogeshkumar L.
A9: 06 | B9: 45840 | C9: General form review and update. Added "Released by, Date, Status, Gate validation Team" for each stage. Removed APQP Risk. Removed unused fields on header. Added/updated/removed items in DV/PV/PDPV stages. Added Category "Automotive/Non Automotive" | D9: J.Muñoz | E9: O.Gutiérrez | F9: M. Yamada
A10: 07 | B10: 45880 | C10: Added RACI Matrix Changed sequence of gates and naming Changed gate items and deliverables Added new columns to assess validity of items General form review and update Added Quality Gate Lead Added Gate Release Team | D10: A. García | E10: A. García | F10: A. García
A11: 08 | B11: 45887 | C11: Split file into different sheets for better visibility and formatting | D11: Jose Lasierra | E11: A. García | F11: A. García
A12: 09 | B12: 46141 | C12: Added Conditional Approval in the project phase | D12: J.Muñoz / O. Gutiérrez | E12: D. Patel | F12: A. García

Sheet APQP GRC Non-Auto (PENDING)
P2: (This column should be hidden)
E3: APQP Gate Release Checklist (APQP GRC) | AA3: Open | AB3: OK | AC3: Automotive | AE3: TBD | AG3: TBD
Q4: GL-00-002-F-001. Ver: 6.0 | AA4: Conditionally closed | AB4: Cond. OK | AC4: Non-Automotive | AE4: PREMO Mediterranée | AG4: Da Nang
D5: Note: All documentation of APQP at respective stage complete, Agreed & Released by Cross-Functional Team. | AA5: Closed | AB5: NO OK | AE5: PREMO Vietnam | AG5: India
B6: *PM must schedule phase review 15 working days with Quality Manager before PVC date and agenda for PVC to be fixed by PM before 3 working days of PVC date. | AB6: N/A | AE6: PREMO Wuhu | AG6: Málaga
E7: Project Manager : | L7: Project Name: | AG7: Tangier
E8: PREMO P/N: | L8: Part Description: | AG8: Wuhu
E9: Customer P/N: | L9: Customer Name:
E10: Samples Center: | L10: Category: | M10: Non-Automotive
E11: Manuf. Center: | L11: Last Rev. Date:
B13: 1 | C13: TEAM + FEASIBILITY (PLANNING) | N13: Evidence | O13: Responsible | P13: Applicable for No Auto | Q13: Status | R13: Evidence (short link) | X13: Remarks / Gaps | Y13: Defined Actions
B14: PFA Feasibility | C14: 1.1 | D14: Team defined, stake holders from key functions/expertise available | N14: Project Information tab in Project Management > Project_information.xls | O14: Project Manager | P14: X
C15: 1.2 | D15: Project Kick off done and information shared with all project team | N15: Project Management > [email or MoM] | O15: Project Manager | P15: X
C16: 1.3 | D16: Project plan | N16: Project Management > Project_information.xls, Tab Timeplan | O16: Project Manager | P16: X
C17: 1.4 | D17: Customer Input Requirements available and clear. | N17: Customer Spec, Email or any evidence of customer request | O17: Sales | P17: X
C18: 1.5 | D18: Preliminary BOM available | N18: Raw Material tab in PDCC and BOM in SAP | O18: R&D | P18: X
C19: 1.6 | D19: Preliminary PREMO Specification | N19: Premo specification "V0" for Feasibility | O19: R&D | P19: X
C20: 1.7 | D20: Design Verification (Samples Inspection Report / SIR) (if applicable) | N20: Sample Inspection Report (SIR) for feasibility samples | O20: Engineering | P20: X
C21: 1.8 | D21: Manufacturing Working Instruction (Samples Inspection Report / SIR) (if applicable) | N21: WI for Feasibility samples (if needed, not mandatory) | O21: Engineering | P21: X
C22: 1.9 | D22: PDCC reviewed | N22: PDCC | O22: Project Team (leaded by PM) | P22: X
C23: 1.10 | D23: Previous DFMEA & Lesson Learnt review | N23: If Lessons learnt applied, to add the Lessons Learnt ID from Database // For DFMEA review, add the reference of the Part Number and DFMEA Ed | O23: Project Team | P23: X
C24: 1.11 | D24: Preliminary List of special product and process characteristics | N24: List of Special Characteristics (if required by customer) in Quality folder OR Characteristics defined in Premo Specification | O24: R&D
C25: 1.12 | D25: Feasibility Study (included in PDCC) | N25: Feasibility tab in PDCC filled | O25: Project Team
C26: 1.13 | D26: Open Issues List reviewed | N26: Check that the the Open Issues List (LOP tab) has been reviewed and the tasks are on time. | O26: Project Manager | P26: X
C27: 1.14 | D27: Risk Assessment & Lesson Learnt Review | N27: Risk assesment tab in Project_information.xls | O27: Project Manager | P27: X
C28: GATE RELEASE RESULT | G28: GATE VALIDATION TEAM: | O28: GATE VALIDATION COMMENTS
C29: Release Status: | E29: Open | G29: R&D Resp | K29: Sales Resp
C30: Released by: | G30: Engineering Resp | K30: Sourcing Resp
C31: Release Date: | G31: Quality Resp | K31: Project Manager
B32: 2 | C32: DESIGN VALIDATION (PRODUCT DESIGN & DEVELOPMENT) | N32: Evidence | O32: Responsible | P32: Yes | Q32: Status | R32: Evidence (short link) | X32: Remarks / Gaps | Y32: Defined Actions
B33: DV Design Validation | C33: 2.1 | D33: DFMEA | N33: DFMEA Creation/Update in SkillFMEA. Includes SC/CC (critical characteristics) | O33: Project Team (leaded by R&D) | Q33: =IF($P$10="Non-automotive", "X", "")
C34: 2.2 | D34: PREMO Specification (including packaging definition) | N34: PREMO Specification approved by Quality in Master List. Includes SC/CC (critical characteristics) | O34: R&D | P34: X
C35: 2.3 | D35: PREMO Raw Material specifications | N35: Premo RM Specifications approved by Quality in Master List. Includes SC/CC (critical characteristics) | O35: R&D | P35: X
C36: 2.4 | D36: Proto-type build Control Plan and Working Instruction (automotive projects with prototypes) | N36: Protype Control Plan and Working Instruction for DV Samples (applicable only for automotive projects when prototypes are required). Includes SC/CC (critical characteristics) | O36: Engineering
C37: 2.5 | D37: Design Verification (Samples Inspection Report / SIR) | N37: SIR for DV Samples | O37: Engineering | P37: X
C38: 2.6 | D38: Definitive Special Product and Process Characterisitcs | N38: Updated List of Special Characteristics (if required by customer) in Quality folder OR Characteristics defined in Premo Specification | O38: R&D/Engineering
C39: 2.7 | D39: Customer Requirements Check List or PREMO Specification acceptance, Customer Specific Requirements cross checked. | N39: Customer Requirement Form (Premo template or customer template) OR Premo specification accepted by customer (signature or email); Check all Customer Requirements. | O39: Project Quality (supported by Project Team) | P39: X
C40: 2.8 | D40: BOM with definitive suppliers | N40: BOM with definitive suppliers form | O40: Sourcing | P40: X
C41: 2.9 | D41: Suppliers Approval Plan (for non-approved suppliers) | N41: Review that all suppliers are approved. If supplier is not approved, approval plan is needed. | O41: Sourcing (supported by SQA) | P41: X
C42: 2.10 | D42: RM PPAP are requested in VEGA | N42: Projects are opened in VEGA | O42: Sourcing | P42: X
...

Sheet IT INFO
E6: PCA
F7: REJECTED
E8: FEASIBILITY
F9: REJECTED
E10: PENDING OFFER ACCEPTANCE
F11: CLOSED LOST
E12: DEVELOPING
F13: CLOSED LOST
E14: SAMPLES
D16: CLOSED WON | F16: CLOSED LOST
